Workbook

Sheet Setup
B2: Budget Calculator
B3: Plan and track your monthly/yearly spending for the school year.
B6: Budget Calculator Template Disclaimer
B7: The numbers on this sample page are for demonstrative purposes on how to use this calculator only and may not reflect accurate numbers. Budgeting for individuals is personal. For more accurate information to input into this spreadsheet to reflect your individual preferences, please visit the links provided on the website and within this sheet to build a calculator that more accurately represents your individual situation.
B9: How to use this template
A10: 1. | B10: Get started by filling out the 'Expenses' and 'Income' tabs. Enter data using one of the 'Per Month', 'Per Term', or 'Per Year' columns for each category row.
A11: 2. | B11: Only edit cells highlighted like this one. Try not to alter cells that contain a formula.
A12: 3. | B12: Feel free to rename or delete categories in the tabs. Your changes will automatically be reflected on the 'Summary' tab, which shows an overview of your projected expenses and income.

Sheet Expenses
C2: EXPENSES | D2: Per Month | E2: Per Term | F2: Per Year | G2: Monthly Total (Projected) | H2: Yearly Total (Projected)
A3: Education | C3: Totals | G3: =sum(G4:G8) -> 697.41667 | H3: =sum(H4:H8) -> 8369
C4: =HYPERLINK("https://www.sfu.ca/students/calendar/fees-and-regulations/tuition-fees/graduate.html","Tuition (per semester)") -> Tuition (per semester) | E4: 2110 | G4: =H4/12 -> 527.5 | H4: =(D4*12)+(E4/4*12)+F4 -> 6330
C5: Student Fees | E5: 250 | G5: =H5/12 -> 62.5 | H5: =(D5*12)+(E5/4*12)+F5 -> 750
C6: Books + Supplies | F6: 800 | G6: =H6/12 -> 66.666667 | H6: =(D6*12)+(E6/4*12)+F6 -> 800
C7: =HYPERLINK("http://www.sfu.ca/students/calendar/fees-and-regulations/tuition-fees/graduate.html#saf","Graduate Student Activity Fee") -> Graduate Student Activity Fee | E7: 76 | G7: =H7/12 -> 19 | H7: =(D7*12)+(E7/4*12)+F7 -> 228
C8: =HYPERLINK("http://www.sfu.ca/students/calendar/fees-and-regulations/tuition-fees/graduate.html#saf","Recreation/Athletic Fees") -> Recreation/Athletic Fees | E8: 87 | G8: =H8/12 -> 21.75 | H8: =(D8*12)+(E8/4*12)+F8 -> 261
A10: Housing + Living | C10: Totals | G10: =sum(G11:G17) -> 2460 | H10: =sum(H11:H17) -> 29520
C11: =HYPERLINK("https://www.sfu.ca/students/residences/housing-options/","Rent") -> Rent | D11: 1450 | G11: =H11/12 -> 1450 | H11: =(D11*12)+(E11/4*12)+F11 -> 17400
C12: Food/Groceries | D12: 600 | G12: =H12/12 -> 600 | H12: =(D12*12)+(E12/4*12)+F12 -> 7200
C13: Utilities | D13: 200 | G13: =H13/12 -> 200 | H13: =(D13*12)+(E13/4*12)+F13 -> 2400
C14: Phone Plan | D14: 75 | G14: =H14/12 -> 75 | H14: =(D14*12)+(E14/4*12)+F14 -> 900
C15: TV/Cable/Streaming | D15: 60 | G15: =H15/12 -> 60 | H15: =(D15*12)+(E15/4*12)+F15 -> 720
C16: Internet | D16: 75 | G16: =H16/12 -> 75 | H16: =(D16*12)+(E16/4*12)+F16 -> 900
C17: Other | G17: =H17/12 -> 0 | H17: =(D17*12)+(E17/4*12)+F17 -> 0
A19: Medical/Health | C19: Totals | G19: =sum(G20:G25) -> 79.166667 | H19: =sum(H20:H25) -> 950
C20: =HYPERLINK("https://www2.gov.bc.ca/gov/content/health/health-drug-coverage/msp","BC MSP") -> BC MSP | D20: 37.5 | G20: =H20/12 -> 37.5 | H20: =(D20*12)+(E20/4*12)+F20 -> 450
C21: =HYPERLINK("http://www.studentcare.ca/View.aspx?locale=en&uid=IHaveAPlan_SFUSimonFraserUniversitygraduatestudentsGSS_Home","GSS Benefit Plan") -> GSS Benefit Plan | F21: 500 | G21: =H21/12 -> 41.666667 | H21: =(D21*12)+(E21/4*12)+F21 -> 500
C22: =HYPERLINK("https://www.sfu.ca/content/dam/sfu/human-resources/forms-documents/benefits/2020-Benefits/TSSU%20Benefit%20Summary%20January%202020.pdf","TSSU Benefits Plan") -> TSSU Benefits Plan | G22: =H22/12 -> 0 | H22: =(D22*12)+(E22/4*12)+F22 -> 0
C23: =HYPERLINK("https://www.guard.me/sfu/","guard.me@SFU Plan") -> guard.me@SFU Plan | G23: =H23/12 -> 0 | H23: =(D23*12)+(E23/4*12)+F23 -> 0
C24: Emergency | G24: =H24/12 -> 0 | H24: =(D24*12)+(E24/4*12)+F24 -> 0
C25: Other | G25: =H25/12 -> 0 | H25: =(D25*12)+(E25/4*12)+F25 -> 0
A27: Transportation | C27: Totals | G27: =sum(G28:G34) -> 86 | H27: =sum(H28:H34) -> 1032
C28: =HYPERLINK("https://www.sfu.ca/students/upass.html","U-Pass") -> U-Pass | E28: 184 | G28: =H28/12 -> 46 | H28: =(D28*12)+(E28/4*12)+F28 -> 552
C29: Gas | G29: =H29/12 -> 0 | H29: =(D29*12)+(E29/4*12)+F29 -> 0
C30: =HYPERLINK("https://www.icbc.com/insurance/Pages/Default.aspx","Car Insurance") -> Car Insurance | G30: =H30/12 -> 0 | H30: =(D30*12)+(E30/4*12)+F30 -> 0
C31: =HYPERLINK("https://www.sfu.ca/parking/rates--payments---forms.html","Parking") -> Parking | G31: =H31/12 -> 0 | H31: =(D31*12)+(E31/4*12)+F31 -> 0
C32: Car Payments | G32: =H32/12 -> 0 | H32: =(D32*12)+(E32/4*12)+F32 -> 0
C33: Taxi/Ride Hailing | D33: 40 | G33: =H33/12 -> 40 | H33: =(D33*12)+(E33/4*12)+F33 -> 480
C34: Other | G34: =H34/12 -> 0 | H34: =(D34*12)+(E34/4*12)+F34 -> 0
A36: Miscellaneous | C36: Totals | G36: =sum(G37:G49) -> 500 | H36: =sum(H37:H49) -> 6000
C37: Recreation | D37: 100 | G37: =H37/12 -> 100 | H37: =(D37*12)+(E37/4*12)+F37 -> 1200
C38: Entertainment | D38: 400 | G38: =H38/12 -> 400 | H38: =(D38*12)+(E38/4*12)+F38 -> 4800
C39: Personal Care | G39: =H39/12 -> 0 | H39: =(D39*12)+(E39/4*12)+F39 -> 0
C40: =HYPERLINK("https://www.sfu.ca/students/isap/explore/family/child-care.html","Child Care") -> Child Care | G40: =H40/12 -> 0 | H40: =(D40*12)+(E40/4*12)+F40 -> 0
C41: Clothing | G41: =H41/12 -> 0 | H41: =(D41*12)+(E41/4*12)+F41 -> 0
C42: Vacation | G42: =H42/12 -> 0 | H42: =(D42*12)+(E42/4*12)+F42 -> 0
C43: Gifts | G43: =H43/12 -> 0 | H43: =(D43*12)+(E43/4*12)+F43 -> 0
C44: Other | G44: =H44/12 -> 0 | H44: =(D44*12)+(E44/4*12)+F44 -> 0
C45: [Category 1] | G45: =H45/12 -> 0 | H45: =(D45*12)+(E45/4*12)+F45 -> 0
...

Sheet Income
C2: INCOME | D2: Per Month | E2: Per Term | F2: Per Year | G2: Monthly Total (Projected) | H2: Yearly Total (Projected)
A3: Income | C3: Totals | G3: =sum(G4:G7) -> 1000 | H3: =sum(H4:H7) -> 12000
C4: =HYPERLINK("https://www.sfu.ca/human-resources/prospective-employees/temporary-support/student-temporary-pool.html","Part-Time Job") -> Part-Time Job | D4: 1000 | G4: =H4/12 -> 1000 | H4: =(D4*12)+(E4/4*12)+F4 -> 12000
C5: Family Contributions | G5: =H5/12 -> 0 | H5: =(D5*12)+(E5/4*12)+F5 -> 0
C6: =HYPERLINK("https://www.sfu.ca/students/financialaid/grad/work-study.html","Work-Study Program") -> Work-Study Program | G6: =H6/12 -> 0 | H6: =(D6*12)+(E6/4*12)+F6 -> 0
C7: Other | G7: =H7/12 -> 0 | H7: =(D7*12)+(E7/4*12)+F7 -> 0
A9: Financial Assistance | C9: Totals | G9: =sum(G10:G12) -> 2875 | H9: =sum(H10:H12) -> 34500
C10: =HYPERLINK("https://www.sfu.ca/students/financialaid/grad/loans/home.html","Government Loans") -> Government Loans | F10: 15000 | G10: =H10/12 -> 1250 | H10: =(D10*12)+(E10/4*12)+F10 -> 15000
C11: =HYPERLINK("http://www.sfu.ca/dean-gradstudies/awards.html","Scholarships/Awards") -> Scholarships/Awards | E11: 5500 | G11: =H11/12 -> 1375 | H11: =(D11*12)+(E11/4*12)+F11 -> 16500
C12: =HYPERLINK("https://www.sfu.ca/students/financialaid/grad/bursaries.html","Bursaries") -> Bursaries | E12: 1000 | G12: =H12/12 -> 250 | H12: =(D12*12)+(E12/4*12)+F12 -> 3000
C13: =HYPERLINK("http://www.tssu.ca/childcare/","TSSU Childcare Fund") -> TSSU Childcare Fund | G13: =H13/12 -> 0 | H13: =(D13*12)+(E13/4*12)+F13 -> 0
C14: =HYPERLINK("http://sfugradsociety.ca/","GSS Financial Support") -> GSS Financial Support | G14: =H14/12 -> 0 | H14: =(D14*12)+(E14/4*12)+F14 -> 0
C15: Other | G15: =H15/12 -> 0 | H15: =(D15*12)+(E15/4*12)+F15 -> 0
A17: Savings + Investments | C17: Totals | G17: =sum(G18:G20) -> 0 | H17: =sum(H18:H20) -> 0
C18: Savings | G18: =H18/12 -> 0 | H18: =(D18*12)+(E18/4*12)+F18 -> 0
C19: Investments | G19: =H19/12 -> 0 | H19: =(D19*12)+(E19/4*12)+F19 -> 0
C20: =HYPERLINK("https://www.canada.ca/en/services/benefits/education/education-savings/resp.html","RESP") -> RESP | G20: =H20/12 -> 0 | H20: =(D20*12)+(E20/4*12)+F20 -> 0
C21: In-Trust | G21: =H21/12 -> 0 | H21: =(D21*12)+(E21/4*12)+F21 -> 0
C22: Other | G22: =H22/12 -> 0 | H22: =(D22*12)+(E22/4*12)+F22 -> 0
A24: Miscellaneous | C24: Totals | G24: =sum(G25:G29) -> 0 | H24: =sum(H25:H29) -> 0
C25: Gifts | G25: =H25/12 -> 0 | H25: =(D25*12)+(E25/4*12)+F25 -> 0
C26: Refunds | G26: =H26/12 -> 0 | H26: =(D26*12)+(E26/4*12)+F26 -> 0
C27: Other | G27: =H27/12 -> 0 | H27: =(D27*12)+(E27/4*12)+F27 -> 0
C28: [Category 1] | G28: =H28/12 -> 0 | H28: =(D28*12)+(E28/4*12)+F28 -> 0
C29: [Category 2] | G29: =H29/12 -> 0 | H29: =(D29*12)+(E29/4*12)+F29 -> 0

Sheet Summary
C3: ABOUT THIS SHEET | J3: NOTE
C4: This sheet generates a summary of your spending based on data in the 'Expenses' and 'Income' tabs. | J4: Please don't edit this sheet.
J5: It contains formulas and will update automatically.
C7: SUMMARY
D8: =Expenses!G2 -> Monthly Total (Projected) | E8: =Expenses!H2 -> Yearly Total (Projected) | G8: =IFERROR(__xludf.DUMMYFUNCTION("SPARKLINE(G14,{""charttype"",""column"";""ymin"", 0; ""ymax"",MAX(G14:H14);""firstcolor"",""#CC0633""})"),"") | H8: =IFERROR(__xludf.DUMMYFUNCTION("SPARKLINE(H14,{""charttype"",""column"";""ymin"", 0; ""ymax"",max(G14:H14);""firstcolor"",""#434343""})"),"") | J8: =D11 -> 52.416667 | K8: =if(J8 < 0, "Deficit in monthly savings", "Surplus in monthly income") -> Surplus in monthly income
C9: Income | D9: =sum(D16:D19) -> 3875 | E9: =sum(E16:E19) -> 46500
C10: Expenses | D10: =sum(D24:D28) -> 3822.5833 | E10: =sum(E24:E28) -> 45871 | J10: =E11 -> 629
C11: Net savings | D11: =D9-D10 -> 52.416667 | E11: =E9-E10 -> 629 | K11: =if(J10 < 0, "Deficit in yearly savings", "Surplus in yearly income") -> Surplus in yearly income
G13: EXPENSES | H13: INCOME
C14: INCOME | G14: =E10 -> 45871 | H14: =E9 -> 46500
B15: Row # | C15: =IFERROR(__xludf.DUMMYFUNCTION("unique(Income!A:A)"),"") | D15: =Income!G2 -> Monthly Total (Projected) | E15: =Income!H2 -> Yearly Total (Projected)
B16: {=iferror(match(C16:C30,Income!A:A,0))} -> #REF! | C16: =IFERROR(__xludf.DUMMYFUNCTION("""COMPUTED_VALUE"""),"Income") -> Income | D16: =Income!G3 -> 1000 | E16: =Income!H3 -> 12000
C17: =IFERROR(__xludf.DUMMYFUNCTION("""COMPUTED_VALUE"""),"Financial Assistance") -> Financial Assistance | D17: =Income!G9 -> 2875 | E17: =Income!H9 -> 34500
C18: =IFERROR(__xludf.DUMMYFUNCTION("""COMPUTED_VALUE"""),"Savings + Investments") -> Savings + Investments | D18: =Income!G17 -> 0 | E18: =Income!H17 -> 0
C19: =IFERROR(__xludf.DUMMYFUNCTION("""COMPUTED_VALUE"""),"Miscellaneous") -> Miscellaneous | D19: =Income!G24 -> 0 | E19: =Income!H24 -> 0
C22: EXPENSES
B23: Row # | C23: =IFERROR(__xludf.DUMMYFUNCTION("unique(Expenses!A:A)"),"") | D23: =Expenses!G2 -> Monthly Total (Projected) | E23: =Expenses!H2 -> Yearly Total (Projected)
B24: {=iferror(match(C24:C30,Expenses!A:A,0))} -> 3 | C24: =IFERROR(__xludf.DUMMYFUNCTION("""COMPUTED_VALUE"""),"Education") -> Education | D24: =Expenses!G3 -> 697.41667 | E24: =Expenses!H3 -> 8369
B25: 10 | C25: =IFERROR(__xludf.DUMMYFUNCTION("""COMPUTED_VALUE"""),"Housing + Living") -> Housing + Living | D25: =Expenses!G10 -> 2460 | E25: =Expenses!H10 -> 29520
B26: 19 | C26: =IFERROR(__xludf.DUMMYFUNCTION("""COMPUTED_VALUE"""),"Medical/Health") -> Medical/Health | D26: =Expenses!G19 -> 79.166667 | E26: =Expenses!H19 -> 950
B27: 27 | C27: =IFERROR(__xludf.DUMMYFUNCTION("""COMPUTED_VALUE"""),"Transportation") -> Transportation | D27: =Expenses!G27 -> 86 | E27: =Expenses!H27 -> 1032
B28: 36 | C28: =IFERROR(__xludf.DUMMYFUNCTION("""COMPUTED_VALUE"""),"Miscellaneous") -> Miscellaneous | D28: =Expenses!G36 -> 500 | E28: =Expenses!H36 -> 6000
